Error: call revert exception [ See: https:
    at Logger.makeError (E:\Learning_Programming\Solidity\SimeplStorageHardHat\node_modules\@ethersproject\logger\src.ts\index.ts:261:28)
    at Logger.throwError (E:\Learning_Programming\Solidity\SimeplStorageHardHat\node_modules\@ethersproject\logger\src.ts\index.ts:273:20)
    at Interface.decodeFunctionResult (E:\Learning_Programming\Solidity\SimeplStorageHardHat\node_modules\@ethersproject\abi\src.ts\interface.ts:427:23)
    at Contract.<anonymous> (E:\Learning_Programming\Solidity\SimeplStorageHardHat\node_modules\@ethersproject\contracts\src.ts\index.ts:400:44)
    at step (E:\Learning_Programming\Solidity\SimeplStorageHardHat\node_modules\@ethersproject\contracts\lib\index.js:48:23)
    at Object.next (E:\Learning_Programming\Solidity\SimeplStorageHardHat\node_modules\@ethersproject\contracts\lib\index.js:29:53)
    at fulfilled (E:\Learning_Programming\Solidity\SimeplStorageHardHat\node_modules\@ethersproject\contracts\lib\index.js:20:58)
    at processTicksAndRejections (node:internal/process/task_queues:96:5) {
  reason: null,
  code: 'CALL_EXCEPTION',
  method: 'people(uint256)',
  data: '0x',
  errorArgs: null,
  errorName: null,
  errorSignature: null,
  address: '0x5FC8d32690cc91D4c39d9d3abcBD16989F875707',
  args: [ '0' ],
  transaction: {
    data: '0x9e7a13ad0000000000000000000000000000000000000000000000000000000000000000',
    to: '0x5FC8d32690cc91D4c39d9d3abcBD16989F875707',
    from: '0xf39Fd6e51aad88F6F4ce6aB8827279cffFb92266'
  }
}
